Workbook

Sheet README
A1: README — Genie API QPM Planner
A2: Bachar Wehbi Silviu Tofan Lydia Ray
A3: 1. Purpose of This Tool This planner helps you estimate the Queries Per Minute (QPM) capacity required to deliver a great user experience for Genie for API-driven applications. Instead of relying on simple averages or rough heuristics, this model simulates your actual traffic patterns, including: - Daily fluctuations (morning, afternoon, global peaks) - Session length and interaction timing - Query behaviour (fast, standard, slow) - Weekend vs weekday usage - Human-driven think-time between queries The goal is to help you choose a QPM reservation that balances: - Performance (minimizing queueing) - Cost efficiency (avoiding over-provisioning) - Real-world user behaviour
A4: 2. Why This Matters Genie and LLM-powered applications behave differently from classic BI dashboards: - Users think, type, interpret, and iterate. - Queries come in bursts, not evenly spaced. - Interaction speed varies drastically between users. - Peaks can come from multiple time zones or multiple departments. Traditional spreadsheet formulas (average users, standard deviation) cannot capture this complexity. This tool helps teams: - Size QPM before adoption or rollout - Identify when peaks exceed capacity - Avoid user frustration caused by queueing - Optimize cost by selecting a reservation that meets SLA needs - Communicate QPM needs clearly to procurement or platform teams
A5: 3. How the Model Works (High-Level) This planner combines user-provided inputs with a daily traffic simulation to compute expected demand. Phase 1 — Base traffic assumptions You provide: - Average + peak users per hour - Session duration - Number of peaks per day - Peak width - Weekend scaling - Interaction behaviour (Fast / Standard / Slow) From these, we compute: - Average concurrent users - Peak concurrent users - Avg and Peak QPM per user Phase 2 — Daily demand modelling The model constructs a 24-hour demand curve: - Gaussian peaks representing load spikes - Evenly spaced peak centers - Adjustable peak sharpness - Separate weekday + weekend curves This becomes the true demand profile that reflects real behaviour. Phase 3 — Applying your QPM reservation You enter the QPM reservation you want to test. The model evaluates: - Where demand exceeds capacity - How many queries would queue - What percentage of the day you’re over the cap - Average utilisation of reserved capacity This output directly drives SLA decisions. Phase 4 — Tradeoff Curve (Reservation vs Queueing) The tool simulates reservation levels from 0 → 200 QPM. For each reservation level, it computes: - % of total queries queued - % of time demand exceeds reservation - Average utilisation This produces the Queueing vs QPM Reservation curve, which shows the optimal balance between: - Cost (QPM purchased) - Performance (user wait times) This is the single most important visualization for decision-making.
A7: NOTE - talk about what happens during queues that are long term (e.g. 10+ minutes); can they make recommendations on non-peak hours based on usage patterns that we see on usage over time

Sheet Planner
A1: Genie API QPM Planner
A3: User Input - Please Modify as Needed
A4: Calculations - Please Do NOT Change
A5: Resulting QPM / Utilisation Metrics - Please Do NOT Change
A7: Usage assumptions (per hour) Define how your users behave during an average and peak hour. These inputs shape the base demand before modelling the full day. | D7: Derived metrics Calculated values that describe your expected demand profile.
A8: Average users per active hour The typical number of users active in a non-peak hour. Used to estimate baseline API/Genie load. | B8: 10 | D8: Average concurrent users The estimated number of users simultaneously active at any given moment during a typical hour. Calculated from: (Average users per hour × Average session duration) / 60 | E8: =B8*B10*B11/60 -> 0.83333333
A9: Peak users in busiest hour The maximum number of users active in the busiest hour of the day (your highest concurrency). Determines peak QPM. | B9: 50 | D9: Peak concurrent users The maximum number of users simultaneously active during the busiest hour of the day. This determines your theoretical peak demand before scaling by interaction behaviour. | E9: =B9*B10*B11/60 -> 4.1666667
A10: Average visit duration (minutes) How long a typical user session lasts. Longer sessions → more concurrent usage. | B10: 10
A11: Adoption rate (%) The percentage of your total population that actually uses the system each hour. Helps scale down large user counts realistically. | B11: 0.5 | D11: Avg QPM (selected scenario) The average number of queries per minute generated during normal load based on your selected interaction style. | E11: =E8*60/B17 -> 0.55555556
A12: Number of peaks per weekday (1, 2, or 3 supported) How many traffic spikes your application has per day (e.g., 1 = midday; 2 = morning + afternoon; 3 = morning + noon + evening). Shapes the daily demand curve. | B12: 2 | D12: Peak QPM (selected scenario) The expected number of queries per minute during the busiest period of the day, reflecting both peak concurrency and interaction speed. | E12: =E9*60/B17 -> 2.7777778
A13: Peak width (hours) Controls how sharp or wide each peak is. Smaller values = sharper spikes. Larger values = broader, flatter peaks. | B13: 3
A15: Interaction behaviour Control how quickly your users issue queries. Scenarios affect overall QPM load. | D15: For chosen QPM reservation Shows how your selected reservation performs under your traffic model.
A16: Chosen scenario Selects a predefined interaction style (Fast, Standard, Slow). | B16: Standard | D16: % queries queued The percentage of total daily queries that exceed your reserved QPM capacity and must wait (i.e., should be put in a queue). | E16: =Engine!C5 -> 0
A17: Selected time per query (seconds) Automatically filled based on the chosen scenario. Represents how long an average interaction takes → affects QPM. | B17: {=INDEX(B21:B23,MATCH(B16,A21:A23,0))} -> 90 | D17: % time above cap The percentage of the day during which demand exceeds your reserved QPM. | E17: =Engine!D5 -> 0
D18: Average utilisation How much of your reserved QPM is actually used on average across the entire day (weekday + weekend). | E18: =Engine!E5 -> 0.077324668
A20: Scenario A scenario represents how quickly your users interact with Genie/API. Specifically, how many seconds it takes a user to submit a query, read the answer, and submit the next one. | B20: Time per query (s) | C20: Avg QPM | D20: Peak QPM
A21: Fast | B21: 45 | C21: =E8*60/B21 -> 1.1111111 | D21: =E9*60/B21 -> 5.5555556
A22: Standard | B22: 90 | C22: =E8*60/B22 -> 0.55555556 | D22: =E9*60/B22 -> 2.7777778
A23: Slow | B23: 150 | C23: =E8*60/B23 -> 0.33333333 | D23: =E9*60/B23 -> 1.6666667
A25: Weekend behaviour
A26: Weekend usage (% of weekday) | C26: 0.2
A28: SLA / business preference
A29: Target % of queries WITHOUT queuing Your desired SLA. Used only for guidance — not part of core calculations. | C29: 0.9999
A31: QPM reservation The QPM limit you plan to reserve/purchase. All queueing, utilisation, and “time above cap” metrics are calculated using this value. | C31: 10

Sheet Engine
A1: BucketMinutes | B1: 15
A2: Weekdays per week | B2: 5 | G2: Peak1 centre | H2: =1/(2*Planner!B12) -> 0.25
A3: Weekend days per week | B3: 2 | G3: Peak2 centre | H3: =IF(Planner!B12>=2,3/(2*Planner!B12),"") -> 0.75
A4: Weeks per month | B4: 4 | G4: Peak3 centre | H4: =IF(Planner!B12>=3,5/(2*Planner!B12),"")
A5: QPM cap (from Planner) | B5: =Planner!C31 -> 10 | C5: =(SUMPRODUCT((D11:D106>B5)*(D11:D106-B5))*$B$1*$B$6+SUMPRODUCT((E11:E106>B5)*(E11:E106-B5))*$B$1*$B$7)/($H$15*$B$6+$H$16*$B$7) -> 0 | D5: =(COUNTIF(D11:D106,">"&B5)*$B$6+COUNTIF(E11:E106,">"&B5)*$B$7)/(ROWS(D11:D106)*($B$6+$B$7)) -> 0 | E5: =(SUMPRODUCT((D11:D106<=B5)*D11:D106 + (D11:D106>B5)*B5)*$B$1*$B$6+SUMPRODUCT((E11:E106<=B5)*E11:E106 + (E11:E106>B5)*B5)*$B$1*$B$7)/(B5*60*24*($B$6+$B$7)) -> 0.077324668 | G5: SigmaHours | H5: =Planner!B13 -> 3
A6: Weekdays in month | B6: =B2*B4 -> 20
A7: Weekend days in month | B7: =B3*B4 -> 8
A8: Overflow tolerance (info only) | B8: =1-Planner!C29 -> 0.0001 | G8: shape_avg | H8: =AVERAGE(C11:C106) -> 1.9543748
G9: shape_max | H9: =MAX(C11:C106) -> 3.1926089
A10: TimeFrac | B10: TimeOfDay | C10: Shape | D10: Weekday QPM | E10: Weekend QPM | F10: Reservation QPM | G10: b_scale | H10: =(Planner!E12-Planner!E11)/(H9-H8) -> 1.7946705
A11: 0 | B11: =A11 -> 0 | C11: =_xlfn.NORM.DIST($A11,$H$2,$H$5/24,FALSE)+IF(Planner!B12>=2,_xlfn.NORM.DIST($A11,$H$3,$H$5/24,FALSE),0)+IF(Planner!B12>=3,_xlfn.NORM.DIST($A11,$H$4,$H$5/24,FALSE),0) -> 0.43192778 | D11: =MAX(0,$H$11+$H$10*C11) -> 0 | E11: =MAX(0,D11*Planner!C26) -> 0 | F11: =Planner!C31 -> 10 | G11: a_offset | H11: =Planner!E11-H10*H8 -> -2.9519032
A12: =A11+B$1/1440 -> 0.010416667 | B12: =A12 -> 0.010416667 | C12: =_xlfn.NORM.DIST($A12,$H$2,$H$5/24,FALSE)+IF(Planner!B12>=2,_xlfn.NORM.DIST($A12,$H$3,$H$5/24,FALSE),0)+IF(Planner!B12>=3,_xlfn.NORM.DIST($A12,$H$4,$H$5/24,FALSE),0) -> 0.50849373 | D12: =MAX(0,$H$11+$H$10*C12) -> 0 | E12: =MAX(0,D12*Planner!C26) -> 0 | F12: =Planner!C31 -> 10
A13: =A12+B$1/1440 -> 0.020833333 | B13: =A13 -> 0.020833333 | C13: =_xlfn.NORM.DIST($A13,$H$2,$H$5/24,FALSE)+IF(Planner!B12>=2,_xlfn.NORM.DIST($A13,$H$3,$H$5/24,FALSE),0)+IF(Planner!B12>=3,_xlfn.NORM.DIST($A13,$H$4,$H$5/24,FALSE),0) -> 0.59448944 | D13: =MAX(0,$H$11+$H$10*C13) -> 0 | E13: =MAX(0,D13*Planner!C26) -> 0 | F13: =Planner!C31 -> 10
A14: =A13+B$1/1440 -> 0.03125 | B14: =A14 -> 0.03125 | C14: =_xlfn.NORM.DIST($A14,$H$2,$H$5/24,FALSE)+IF(Planner!B12>=2,_xlfn.NORM.DIST($A14,$H$3,$H$5/24,FALSE),0)+IF(Planner!B12>=3,_xlfn.NORM.DIST($A14,$H$4,$H$5/24,FALSE),0) -> 0.69021876 | D14: =MAX(0,$H$11+$H$10*C14) -> 0 | E14: =MAX(0,D14*Planner!C26) -> 0 | F14: =Planner!C31 -> 10
A15: =A14+B$1/1440 -> 0.041666667 | B15: =A15 -> 0.041666667 | C15: =_xlfn.NORM.DIST($A15,$H$2,$H$5/24,FALSE)+IF(Planner!B12>=2,_xlfn.NORM.DIST($A15,$H$3,$H$5/24,FALSE),0)+IF(Planner!B12>=3,_xlfn.NORM.DIST($A15,$H$4,$H$5/24,FALSE),0) -> 0.79581745 | D15: =MAX(0,$H$11+$H$10*C15) -> 0 | E15: =MAX(0,D15*Planner!C26) -> 0 | F15: =Planner!C31 -> 10 | G15: Weekday total queries | H15: =SUM(D11:D106)*$B$1 -> 1443.3938
A16: =A15+B$1/1440 -> 0.052083333 | B16: =A16 -> 0.052083333 | C16: =_xlfn.NORM.DIST($A16,$H$2,$H$5/24,FALSE)+IF(Planner!B12>=2,_xlfn.NORM.DIST($A16,$H$3,$H$5/24,FALSE),0)+IF(Planner!B12>=3,_xlfn.NORM.DIST($A16,$H$4,$H$5/24,FALSE),0) -> 0.9112221 | D16: =MAX(0,$H$11+$H$10*C16) -> 0 | E16: =MAX(0,D16*Planner!C26) -> 0 | F16: =Planner!C31 -> 10 | G16: Weekend total queries | H16: =SUM(E11:E106)*$B$1 -> 288.67876
A17: =A16+B$1/1440 -> 0.0625 | B17: =A17 -> 0.0625 | C17: =_xlfn.NORM.DIST($A17,$H$2,$H$5/24,FALSE)+IF(Planner!B12>=2,_xlfn.NORM.DIST($A17,$H$3,$H$5/24,FALSE),0)+IF(Planner!B12>=3,_xlfn.NORM.DIST($A17,$H$4,$H$5/24,FALSE),0) -> 1.0361416 | D17: =MAX(0,$H$11+$H$10*C17) -> 0 | E17: =MAX(0,D17*Planner!C26) -> 0 | F17: =Planner!C31 -> 10
A18: =A17+B$1/1440 -> 0.072916667 | B18: =A18 -> 0.072916667 | C18: =_xlfn.NORM.DIST($A18,$H$2,$H$5/24,FALSE)+IF(Planner!B12>=2,_xlfn.NORM.DIST($A18,$H$3,$H$5/24,FALSE),0)+IF(Planner!B12>=3,_xlfn.NORM.DIST($A18,$H$4,$H$5/24,FALSE),0) -> 1.170033 | D18: =MAX(0,$H$11+$H$10*C18) -> 0 | E18: =MAX(0,D18*Planner!C26) -> 0 | F18: =Planner!C31 -> 10
A19: =A18+B$1/1440 -> 0.083333333 | B19: =A19 -> 0.083333333 | C19: =_xlfn.NORM.DIST($A19,$H$2,$H$5/24,FALSE)+IF(Planner!B12>=2,_xlfn.NORM.DIST($A19,$H$3,$H$5/24,FALSE),0)+IF(Planner!B12>=3,_xlfn.NORM.DIST($A19,$H$4,$H$5/24,FALSE),0) -> 1.3120827 | D19: =MAX(0,$H$11+$H$10*C19) -> 0 | E19: =MAX(0,D19*Planner!C26) -> 0 | F19: =Planner!C31 -> 10 | G19: Weekday time buckets above reservation | I19: =countif(D11:D106, ">"&B5) -> 0
A20: =A19+B$1/1440 -> 0.09375 | B20: =A20 -> 0.09375 | C20: =_xlfn.NORM.DIST($A20,$H$2,$H$5/24,FALSE)+IF(Planner!B12>=2,_xlfn.NORM.DIST($A20,$H$3,$H$5/24,FALSE),0)+IF(Planner!B12>=3,_xlfn.NORM.DIST($A20,$H$4,$H$5/24,FALSE),0) -> 1.461196 | D20: =MAX(0,$H$11+$H$10*C20) -> 0 | E20: =MAX(0,D20*Planner!C26) -> 0 | F20: =Planner!C31 -> 10 | G20: Weekend time buckets above reservation | I20: =COUNTIF(E11:E106, ">"&B5) -> 0
A21: =A20+B$1/1440 -> 0.10416667 | B21: =A21 -> 0.10416667 | C21: =_xlfn.NORM.DIST($A21,$H$2,$H$5/24,FALSE)+IF(Planner!B12>=2,_xlfn.NORM.DIST($A21,$H$3,$H$5/24,FALSE),0)+IF(Planner!B12>=3,_xlfn.NORM.DIST($A21,$H$4,$H$5/24,FALSE),0) -> 1.6159946 | D21: =MAX(0,$H$11+$H$10*C21) -> 0 | E21: =MAX(0,D21*Planner!C26) -> 0 | F21: =Planner!C31 -> 10
A22: =A21+B$1/1440 -> 0.11458333 | B22: =A22 -> 0.11458333 | C22: =_xlfn.NORM.DIST($A22,$H$2,$H$5/24,FALSE)+IF(Planner!B12>=2,_xlfn.NORM.DIST($A22,$H$3,$H$5/24,FALSE),0)+IF(Planner!B12>=3,_xlfn.NORM.DIST($A22,$H$4,$H$5/24,FALSE),0) -> 1.7748251 | D22: =MAX(0,$H$11+$H$10*C22) -> 0.23332298 | E22: =MAX(0,D22*Planner!C26) -> 0.046664595 | F22: =Planner!C31 -> 10
A23: =A22+B$1/1440 -> 0.125 | B23: =A23 -> 0.125 | C23: =_xlfn.NORM.DIST($A23,$H$2,$H$5/24,FALSE)+IF(Planner!B12>=2,_xlfn.NORM.DIST($A23,$H$3,$H$5/24,FALSE),0)+IF(Planner!B12>=3,_xlfn.NORM.DIST($A23,$H$4,$H$5/24,FALSE),0) -> 1.9357777 | D23: =MAX(0,$H$11+$H$10*C23) -> 0.52217993 | E23: =MAX(0,D23*Planner!C26) -> 0.10443599 | F23: =Planner!C31 -> 10
A24: =A23+B$1/1440 -> 0.13541667 | B24: =A24 -> 0.13541667 | C24: =_xlfn.NORM.DIST($A24,$H$2,$H$5/24,FALSE)+IF(Planner!B12>=2,_xlfn.NORM.DIST($A24,$H$3,$H$5/24,FALSE),0)+IF(Planner!B12>=3,_xlfn.NORM.DIST($A24,$H$4,$H$5/24,FALSE),0) -> 2.0967168 | D24: =MAX(0,$H$11+$H$10*C24) -> 0.8110126 | E24: =MAX(0,D24*Planner!C26) -> 0.16220252 | F24: =Planner!C31 -> 10
A25: =A24+B$1/1440 -> 0.14583333 | B25: =A25 -> 0.14583333 | C25: =_xlfn.NORM.DIST($A25,$H$2,$H$5/24,FALSE)+IF(Planner!B12>=2,_xlfn.NORM.DIST($A25,$H$3,$H$5/24,FALSE),0)+IF(Planner!B12>=3,_xlfn.NORM.DIST($A25,$H$4,$H$5/24,FALSE),0) -> 2.255322 | D25: =MAX(0,$H$11+$H$10*C25) -> 1.0956567 | E25: =MAX(0,D25*Planner!C26) -> 0.21913133 | F25: =Planner!C31 -> 10
A26: =A25+B$1/1440 -> 0.15625 | B26: =A26 -> 0.15625 | C26: =_xlfn.NORM.DIST($A26,$H$2,$H$5/24,FALSE)+IF(Planner!B12>=2,_xlfn.NORM.DIST($A26,$H$3,$H$5/24,FALSE),0)+IF(Planner!B12>=3,_xlfn.NORM.DIST($A26,$H$4,$H$5/24,FALSE),0) -> 2.4091397 | D26: =MAX(0,$H$11+$H$10*C26) -> 1.3717087 | E26: =MAX(0,D26*Planner!C26) -> 0.27434175 | F26: =Planner!C31 -> 10
A27: =A26+B$1/1440 -> 0.16666667 | B27: =A27 -> 0.16666667 | C27: =_xlfn.NORM.DIST($A27,$H$2,$H$5/24,FALSE)+IF(Planner!B12>=2,_xlfn.NORM.DIST($A27,$H$3,$H$5/24,FALSE),0)+IF(Planner!B12>=3,_xlfn.NORM.DIST($A27,$H$4,$H$5/24,FALSE),0) -> 2.5556436 | D27: =MAX(0,$H$11+$H$10*C27) -> 1.634635 | E27: =MAX(0,D27*Planner!C26) -> 0.326927 | F27: =Planner!C31 -> 10
A28: =A27+B$1/1440 -> 0.17708333 | B28: =A28 -> 0.17708333 | C28: =_xlfn.NORM.DIST($A28,$H$2,$H$5/24,FALSE)+IF(Planner!B12>=2,_xlfn.NORM.DIST($A28,$H$3,$H$5/24,FALSE),0)+IF(Planner!B12>=3,_xlfn.NORM.DIST($A28,$H$4,$H$5/24,FALSE),0) -> 2.6923022 | D28: =MAX(0,$H$11+$H$10*C28) -> 1.8798921 | E28: =MAX(0,D28*Planner!C26) -> 0.37597841 | F28: =Planner!C31 -> 10
A29: =A28+B$1/1440 -> 0.1875 | B29: =A29 -> 0.1875 | C29: =_xlfn.NORM.DIST($A29,$H$2,$H$5/24,FALSE)+IF(Planner!B12>=2,_xlfn.NORM.DIST($A29,$H$3,$H$5/24,FALSE),0)+IF(Planner!B12>=3,_xlfn.NORM.DIST($A29,$H$4,$H$5/24,FALSE),0) -> 2.8166505 | D29: =MAX(0,$H$11+$H$10*C29) -> 2.1030563 | E29: =MAX(0,D29*Planner!C26) -> 0.42061127 | F29: =Planner!C31 -> 10
A30: =A29+B$1/1440 -> 0.19791667 | B30: =A30 -> 0.19791667 | C30: =_xlfn.NORM.DIST($A30,$H$2,$H$5/24,FALSE)+IF(Planner!B12>=2,_xlfn.NORM.DIST($A30,$H$3,$H$5/24,FALSE),0)+IF(Planner!B12>=3,_xlfn.NORM.DIST($A30,$H$4,$H$5/24,FALSE),0) -> 2.9263643 | D30: =MAX(0,$H$11+$H$10*C30) -> 2.2999565 | E30: =MAX(0,D30*Planner!C26) -> 0.45999131 | F30: =Planner!C31 -> 10
A31: =A30+B$1/1440 -> 0.20833333 | B31: =A31 -> 0.20833333 | C31: =_xlfn.NORM.DIST($A31,$H$2,$H$5/24,FALSE)+IF(Planner!B12>=2,_xlfn.NORM.DIST($A31,$H$3,$H$5/24,FALSE),0)+IF(Planner!B12>=3,_xlfn.NORM.DIST($A31,$H$4,$H$5/24,FALSE),0) -> 3.0193328 | D31: =MAX(0,$H$11+$H$10*C31) -> 2.4668043 | E31: =MAX(0,D31*Planner!C26) -> 0.49336086 | F31: =Planner!C31 -> 10
A32: =A31+B$1/1440 -> 0.21875 | B32: =A32 -> 0.21875 | C32: =_xlfn.NORM.DIST($A32,$H$2,$H$5/24,FALSE)+IF(Planner!B12>=2,_xlfn.NORM.DIST($A32,$H$3,$H$5/24,FALSE),0)+IF(Planner!B12>=3,_xlfn.NORM.DIST($A32,$H$4,$H$5/24,FALSE),0) -> 3.0937267 | D32: =MAX(0,$H$11+$H$10*C32) -> 2.6003168 | E32: =MAX(0,D32*Planner!C26) -> 0.52006336 | F32: =Planner!C31 -> 10
A33: =A32+B$1/1440 -> 0.22916667 | B33: =A33 -> 0.22916667 | C33: =_xlfn.NORM.DIST($A33,$H$2,$H$5/24,FALSE)+IF(Planner!B12>=2,_xlfn.NORM.DIST($A33,$H$3,$H$5/24,FALSE),0)+IF(Planner!B12>=3,_xlfn.NORM.DIST($A33,$H$4,$H$5/24,FALSE),0) -> 3.1480598 | D33: =MAX(0,$H$11+$H$10*C33) -> 2.6978269 | E33: =MAX(0,D33*Planner!C26) -> 0.53956538 | F33: =Planner!C31 -> 10
A34: =A33+B$1/1440 -> 0.23958333 | B34: =A34 -> 0.23958333 | C34: =_xlfn.NORM.DIST($A34,$H$2,$H$5/24,FALSE)+IF(Planner!B12>=2,_xlfn.NORM.DIST($A34,$H$3,$H$5/24,FALSE),0)+IF(Planner!B12>=3,_xlfn.NORM.DIST($A34,$H$4,$H$5/24,FALSE),0) -> 3.1812402 | D34: =MAX(0,$H$11+$H$10*C34) -> 2.7573748 | E34: =MAX(0,D34*Planner!C26) -> 0.55147495 | F34: =Planner!C31 -> 10
A35: =A34+B$1/1440 -> 0.25 | B35: =A35 -> 0.25 | C35: =_xlfn.NORM.DIST($A35,$H$2,$H$5/24,FALSE)+IF(Planner!B12>=2,_xlfn.NORM.DIST($A35,$H$3,$H$5/24,FALSE),0)+IF(Planner!B12>=3,_xlfn.NORM.DIST($A35,$H$4,$H$5/24,FALSE),0) -> 3.1926089 | D35: =MAX(0,$H$11+$H$10*C35) -> 2.7777778 | E35: =MAX(0,D35*Planner!C26) -> 0.55555556 | F35: =Planner!C31 -> 10
A36: =A35+B$1/1440 -> 0.26041667 | B36: =A36 -> 0.26041667 | C36: =_xlfn.NORM.DIST($A36,$H$2,$H$5/24,FALSE)+IF(Planner!B12>=2,_xlfn.NORM.DIST($A36,$H$3,$H$5/24,FALSE),0)+IF(Planner!B12>=3,_xlfn.NORM.DIST($A36,$H$4,$H$5/24,FALSE),0) -> 3.1819648 | D36: =MAX(0,$H$11+$H$10*C36) -> 2.7586751 | E36: =MAX(0,D36*Planner!C26) -> 0.55173501 | F36: =Planner!C31 -> 10
A37: =A36+B$1/1440 -> 0.27083333 | B37: =A37 -> 0.27083333 | C37: =_xlfn.NORM.DIST($A37,$H$2,$H$5/24,FALSE)+IF(Planner!B12>=2,_xlfn.NORM.DIST($A37,$H$3,$H$5/24,FALSE),0)+IF(Planner!B12>=3,_xlfn.NORM.DIST($A37,$H$4,$H$5/24,FALSE),0) -> 3.1495743 | D37: =MAX(0,$H$11+$H$10*C37) -> 2.7005449 | E37: =MAX(0,D37*Planner!C26) -> 0.54010897 | F37: =Planner!C31 -> 10
A38: =A37+B$1/1440 -> 0.28125 | B38: =A38 -> 0.28125 | C38: =_xlfn.NORM.DIST($A38,$H$2,$H$5/24,FALSE)+IF(Planner!B12>=2,_xlfn.NORM.DIST($A38,$H$3,$H$5/24,FALSE),0)+IF(Planner!B12>=3,_xlfn.NORM.DIST($A38,$H$4,$H$5/24,FALSE),0) -> 3.0961657 | D38: =MAX(0,$H$11+$H$10*C38) -> 2.604694 | E38: =MAX(0,D38*Planner!C26) -> 0.52093881 | F38: =Planner!C31 -> 10
A39: =A38+B$1/1440 -> 0.29166667 | B39: =A39 -> 0.29166667 | C39: =_xlfn.NORM.DIST($A39,$H$2,$H$5/24,FALSE)+IF(Planner!B12>=2,_xlfn.NORM.DIST($A39,$H$3,$H$5/24,FALSE),0)+IF(Planner!B12>=3,_xlfn.NORM.DIST($A39,$H$4,$H$5/24,FALSE),0) -> 3.022908 | D39: =MAX(0,$H$11+$H$10*C39) -> 2.4732206 | E39: =MAX(0,D39*Planner!C26) -> 0.49464412 | F39: =Planner!C31 -> 10
A40: =A39+B$1/1440 -> 0.30208333 | B40: =A40 -> 0.30208333 | C40: =_xlfn.NORM.DIST($A40,$H$2,$H$5/24,FALSE)+IF(Planner!B12>=2,_xlfn.NORM.DIST($A40,$H$3,$H$5/24,FALSE),0)+IF(Planner!B12>=3,_xlfn.NORM.DIST($A40,$H$4,$H$5/24,FALSE),0) -> 2.9313761 | D40: =MAX(0,$H$11+$H$10*C40) -> 2.3089511 | E40: =MAX(0,D40*Planner!C26) -> 0.46179021 | F40: =Planner!C31 -> 10
...

Sheet Tradeoff
A1: Reservation_QPM | B1: %_queries_queued | C1: %_time_above_cap | D1: Avg_utilisation
A2: 0 | B2: =IF(A2=0,1,(SUMPRODUCT((Engine!D$11:D$106>A2)*(Engine!D$11:D$106-A2))*Engine!B$1*Engine!B$6+SUMPRODUCT((Engine!E$11:E$106>A2)*(Engine!E$11:E$106-A2))*Engine!B$1*Engine!B$7)/(Engine!H$15*Engine!B$6+Engine!H$16*Engine!B$7)) -> 1 | C2: =IF(A2=0,1,(COUNTIF(Engine!D$11:D$106,">"&A2)*Engine!B$6+COUNTIF(Engine!E$11:E$106,">"&A2)*Engine!B$7)/(ROWS(Engine!D$11:D$106)*(Engine!B$6+Engine!B$7))) -> 1 | D2: =IF(A2=0,0,(SUMPRODUCT((Engine!D$11:D$106<=A2)*Engine!D$11:D$106 + (Engine!D$11:D$106>A2)*A2)*Engine!B$1*Engine!B$6+SUMPRODUCT((Engine!E$11:E$106<=A2)*Engine!E$11:E$106 + (Engine!E$11:E$106>A2)*A2)*Engine!B$1*Engine!B$7)/(A2*60*24*(Engine!B$6+Engine!B$7))) -> 0
A3: =A2+10 -> 10 | B3: =IF(A3=0,1,(SUMPRODUCT((Engine!D$11:D$106>A3)*(Engine!D$11:D$106-A3))*Engine!B$1*Engine!B$6+SUMPRODUCT((Engine!E$11:E$106>A3)*(Engine!E$11:E$106-A3))*Engine!B$1*Engine!B$7)/(Engine!H$15*Engine!B$6+Engine!H$16*Engine!B$7)) -> 0 | C3: =IF(A3=0,1,(COUNTIF(Engine!D$11:D$106,">"&A3)*Engine!B$6+COUNTIF(Engine!E$11:E$106,">"&A3)*Engine!B$7)/(ROWS(Engine!D$11:D$106)*(Engine!B$6+Engine!B$7))) -> 0 | D3: =IF(A3=0,0,(SUMPRODUCT((Engine!D$11:D$106<=A3)*Engine!D$11:D$106 + (Engine!D$11:D$106>A3)*A3)*Engine!B$1*Engine!B$6+SUMPRODUCT((Engine!E$11:E$106<=A3)*Engine!E$11:E$106 + (Engine!E$11:E$106>A3)*A3)*Engine!B$1*Engine!B$7)/(A3*60*34*(Engine!B$6+Engine!B$7))) -> 0.054582119
A4: =A3+10 -> 20 | B4: =IF(A4=0,1,(SUMPRODUCT((Engine!D$11:D$106>A4)*(Engine!D$11:D$106-A4))*Engine!B$1*Engine!B$6+SUMPRODUCT((Engine!E$11:E$106>A4)*(Engine!E$11:E$106-A4))*Engine!B$1*Engine!B$7)/(Engine!H$15*Engine!B$6+Engine!H$16*Engine!B$7)) -> 0 | C4: =IF(A4=0,1,(COUNTIF(Engine!D$11:D$106,">"&A4)*Engine!B$6+COUNTIF(Engine!E$11:E$106,">"&A4)*Engine!B$7)/(ROWS(Engine!D$11:D$106)*(Engine!B$6+Engine!B$7))) -> 0 | D4: =IF(A4=0,0,(SUMPRODUCT((Engine!D$11:D$106<=A4)*Engine!D$11:D$106 + (Engine!D$11:D$106>A4)*A4)*Engine!B$1*Engine!B$6+SUMPRODUCT((Engine!E$11:E$106<=A4)*Engine!E$11:E$106 + (Engine!E$11:E$106>A4)*A4)*Engine!B$1*Engine!B$7)/(A4*60*44*(Engine!B$6+Engine!B$7))) -> 0.021088546
A5: =A4+10 -> 30 | B5: =IF(A5=0,1,(SUMPRODUCT((Engine!D$11:D$106>A5)*(Engine!D$11:D$106-A5))*Engine!B$1*Engine!B$6+SUMPRODUCT((Engine!E$11:E$106>A5)*(Engine!E$11:E$106-A5))*Engine!B$1*Engine!B$7)/(Engine!H$15*Engine!B$6+Engine!H$16*Engine!B$7)) -> 0 | C5: =IF(A5=0,1,(COUNTIF(Engine!D$11:D$106,">"&A5)*Engine!B$6+COUNTIF(Engine!E$11:E$106,">"&A5)*Engine!B$7)/(ROWS(Engine!D$11:D$106)*(Engine!B$6+Engine!B$7))) -> 0 | D5: =IF(A5=0,0,(SUMPRODUCT((Engine!D$11:D$106<=A5)*Engine!D$11:D$106 + (Engine!D$11:D$106>A5)*A5)*Engine!B$1*Engine!B$6+SUMPRODUCT((Engine!E$11:E$106<=A5)*Engine!E$11:E$106 + (Engine!E$11:E$106>A5)*A5)*Engine!B$1*Engine!B$7)/(A5*60*54*(Engine!B$6+Engine!B$7))) -> 0.011455506
A6: =A5+10 -> 40 | B6: =IF(A6=0,1,(SUMPRODUCT((Engine!D$11:D$106>A6)*(Engine!D$11:D$106-A6))*Engine!B$1*Engine!B$6+SUMPRODUCT((Engine!E$11:E$106>A6)*(Engine!E$11:E$106-A6))*Engine!B$1*Engine!B$7)/(Engine!H$15*Engine!B$6+Engine!H$16*Engine!B$7)) -> 0 | C6: =IF(A6=0,1,(COUNTIF(Engine!D$11:D$106,">"&A6)*Engine!B$6+COUNTIF(Engine!E$11:E$106,">"&A6)*Engine!B$7)/(ROWS(Engine!D$11:D$106)*(Engine!B$6+Engine!B$7))) -> 0 | D6: =IF(A6=0,0,(SUMPRODUCT((Engine!D$11:D$106<=A6)*Engine!D$11:D$106 + (Engine!D$11:D$106>A6)*A6)*Engine!B$1*Engine!B$6+SUMPRODUCT((Engine!E$11:E$106<=A6)*Engine!E$11:E$106 + (Engine!E$11:E$106>A6)*A6)*Engine!B$1*Engine!B$7)/(A6*60*64*(Engine!B$6+Engine!B$7))) -> 0.0072491876
A7: =A6+10 -> 50 | B7: =IF(A7=0,1,(SUMPRODUCT((Engine!D$11:D$106>A7)*(Engine!D$11:D$106-A7))*Engine!B$1*Engine!B$6+SUMPRODUCT((Engine!E$11:E$106>A7)*(Engine!E$11:E$106-A7))*Engine!B$1*Engine!B$7)/(Engine!H$15*Engine!B$6+Engine!H$16*Engine!B$7)) -> 0 | C7: =IF(A7=0,1,(COUNTIF(Engine!D$11:D$106,">"&A7)*Engine!B$6+COUNTIF(Engine!E$11:E$106,">"&A7)*Engine!B$7)/(ROWS(Engine!D$11:D$106)*(Engine!B$6+Engine!B$7))) -> 0 | D7: =IF(A7=0,0,(SUMPRODUCT((Engine!D$11:D$106<=A7)*Engine!D$11:D$106 + (Engine!D$11:D$106>A7)*A7)*Engine!B$1*Engine!B$6+SUMPRODUCT((Engine!E$11:E$106<=A7)*Engine!E$11:E$106 + (Engine!E$11:E$106>A7)*A7)*Engine!B$1*Engine!B$7)/(A7*60*74*(Engine!B$6+Engine!B$7))) -> 0.0050156542
A8: =A7+10 -> 60 | B8: =IF(A8=0,1,(SUMPRODUCT((Engine!D$11:D$106>A8)*(Engine!D$11:D$106-A8))*Engine!B$1*Engine!B$6+SUMPRODUCT((Engine!E$11:E$106>A8)*(Engine!E$11:E$106-A8))*Engine!B$1*Engine!B$7)/(Engine!H$15*Engine!B$6+Engine!H$16*Engine!B$7)) -> 0 | C8: =IF(A8=0,1,(COUNTIF(Engine!D$11:D$106,">"&A8)*Engine!B$6+COUNTIF(Engine!E$11:E$106,">"&A8)*Engine!B$7)/(ROWS(Engine!D$11:D$106)*(Engine!B$6+Engine!B$7))) -> 0 | D8: =IF(A8=0,0,(SUMPRODUCT((Engine!D$11:D$106<=A8)*Engine!D$11:D$106 + (Engine!D$11:D$106>A8)*A8)*Engine!B$1*Engine!B$6+SUMPRODUCT((Engine!E$11:E$106<=A8)*Engine!E$11:E$106 + (Engine!E$11:E$106>A8)*A8)*Engine!B$1*Engine!B$7)/(A8*60*84*(Engine!B$6+Engine!B$7))) -> 0.0036821271
A9: =A8+10 -> 70 | B9: =IF(A9=0,1,(SUMPRODUCT((Engine!D$11:D$106>A9)*(Engine!D$11:D$106-A9))*Engine!B$1*Engine!B$6+SUMPRODUCT((Engine!E$11:E$106>A9)*(Engine!E$11:E$106-A9))*Engine!B$1*Engine!B$7)/(Engine!H$15*Engine!B$6+Engine!H$16*Engine!B$7)) -> 0 | C9: =IF(A9=0,1,(COUNTIF(Engine!D$11:D$106,">"&A9)*Engine!B$6+COUNTIF(Engine!E$11:E$106,">"&A9)*Engine!B$7)/(ROWS(Engine!D$11:D$106)*(Engine!B$6+Engine!B$7))) -> 0 | D9: =IF(A9=0,0,(SUMPRODUCT((Engine!D$11:D$106<=A9)*Engine!D$11:D$106 + (Engine!D$11:D$106>A9)*A9)*Engine!B$1*Engine!B$6+SUMPRODUCT((Engine!E$11:E$106<=A9)*Engine!E$11:E$106 + (Engine!E$11:E$106>A9)*A9)*Engine!B$1*Engine!B$7)/(A9*60*94*(Engine!B$6+Engine!B$7))) -> 0.0028203526
A10: =A9+10 -> 80 | B10: =IF(A10=0,1,(SUMPRODUCT((Engine!D$11:D$106>A10)*(Engine!D$11:D$106-A10))*Engine!B$1*Engine!B$6+SUMPRODUCT((Engine!E$11:E$106>A10)*(Engine!E$11:E$106-A10))*Engine!B$1*Engine!B$7)/(Engine!H$15*Engine!B$6+Engine!H$16*Engine!B$7)) -> 0 | C10: =IF(A10=0,1,(COUNTIF(Engine!D$11:D$106,">"&A10)*Engine!B$6+COUNTIF(Engine!E$11:E$106,">"&A10)*Engine!B$7)/(ROWS(Engine!D$11:D$106)*(Engine!B$6+Engine!B$7))) -> 0 | D10: =IF(A10=0,0,(SUMPRODUCT((Engine!D$11:D$106<=A10)*Engine!D$11:D$106 + (Engine!D$11:D$106>A10)*A10)*Engine!B$1*Engine!B$6+SUMPRODUCT((Engine!E$11:E$106<=A10)*Engine!E$11:E$106 + (Engine!E$11:E$106>A10)*A10)*Engine!B$1*Engine!B$7)/(A10*60*104*(Engine!B$6+Engine!B$7))) -> 0.0022305193
A11: =A10+10 -> 90 | B11: =IF(A11=0,1,(SUMPRODUCT((Engine!D$11:D$106>A11)*(Engine!D$11:D$106-A11))*Engine!B$1*Engine!B$6+SUMPRODUCT((Engine!E$11:E$106>A11)*(Engine!E$11:E$106-A11))*Engine!B$1*Engine!B$7)/(Engine!H$15*Engine!B$6+Engine!H$16*Engine!B$7)) -> 0 | C11: =IF(A11=0,1,(COUNTIF(Engine!D$11:D$106,">"&A11)*Engine!B$6+COUNTIF(Engine!E$11:E$106,">"&A11)*Engine!B$7)/(ROWS(Engine!D$11:D$106)*(Engine!B$6+Engine!B$7))) -> 0 | D11: =IF(A11=0,0,(SUMPRODUCT((Engine!D$11:D$106<=A11)*Engine!D$11:D$106 + (Engine!D$11:D$106>A11)*A11)*Engine!B$1*Engine!B$6+SUMPRODUCT((Engine!E$11:E$106<=A11)*Engine!E$11:E$106 + (Engine!E$11:E$106>A11)*A11)*Engine!B$1*Engine!B$7)/(A11*60*114*(Engine!B$6+Engine!B$7))) -> 0.0018087642
A12: =A11+10 -> 100 | B12: =IF(A12=0,1,(SUMPRODUCT((Engine!D$11:D$106>A12)*(Engine!D$11:D$106-A12))*Engine!B$1*Engine!B$6+SUMPRODUCT((Engine!E$11:E$106>A12)*(Engine!E$11:E$106-A12))*Engine!B$1*Engine!B$7)/(Engine!H$15*Engine!B$6+Engine!H$16*Engine!B$7)) -> 0 | C12: =IF(A12=0,1,(COUNTIF(Engine!D$11:D$106,">"&A12)*Engine!B$6+COUNTIF(Engine!E$11:E$106,">"&A12)*Engine!B$7)/(ROWS(Engine!D$11:D$106)*(Engine!B$6+Engine!B$7))) -> 0 | D12: =IF(A12=0,0,(SUMPRODUCT((Engine!D$11:D$106<=A12)*Engine!D$11:D$106 + (Engine!D$11:D$106>A12)*A12)*Engine!B$1*Engine!B$6+SUMPRODUCT((Engine!E$11:E$106<=A12)*Engine!E$11:E$106 + (Engine!E$11:E$106>A12)*A12)*Engine!B$1*Engine!B$7)/(A12*60*124*(Engine!B$6+Engine!B$7))) -> 0.0014966065
A13: =A12+10 -> 110 | B13: =IF(A13=0,1,(SUMPRODUCT((Engine!D$11:D$106>A13)*(Engine!D$11:D$106-A13))*Engine!B$1*Engine!B$6+SUMPRODUCT((Engine!E$11:E$106>A13)*(Engine!E$11:E$106-A13))*Engine!B$1*Engine!B$7)/(Engine!H$15*Engine!B$6+Engine!H$16*Engine!B$7)) -> 0 | C13: =IF(A13=0,1,(COUNTIF(Engine!D$11:D$106,">"&A13)*Engine!B$6+COUNTIF(Engine!E$11:E$106,">"&A13)*Engine!B$7)/(ROWS(Engine!D$11:D$106)*(Engine!B$6+Engine!B$7))) -> 0 | D13: =IF(A13=0,0,(SUMPRODUCT((Engine!D$11:D$106<=A13)*Engine!D$11:D$106 + (Engine!D$11:D$106>A13)*A13)*Engine!B$1*Engine!B$6+SUMPRODUCT((Engine!E$11:E$106<=A13)*Engine!E$11:E$106 + (Engine!E$11:E$106>A13)*A13)*Engine!B$1*Engine!B$7)/(A13*60*134*(Engine!B$6+Engine!B$7))) -> 0.0012590177
A14: =A13+10 -> 120 | B14: =IF(A14=0,1,(SUMPRODUCT((Engine!D$11:D$106>A14)*(Engine!D$11:D$106-A14))*Engine!B$1*Engine!B$6+SUMPRODUCT((Engine!E$11:E$106>A14)*(Engine!E$11:E$106-A14))*Engine!B$1*Engine!B$7)/(Engine!H$15*Engine!B$6+Engine!H$16*Engine!B$7)) -> 0 | C14: =IF(A14=0,1,(COUNTIF(Engine!D$11:D$106,">"&A14)*Engine!B$6+COUNTIF(Engine!E$11:E$106,">"&A14)*Engine!B$7)/(ROWS(Engine!D$11:D$106)*(Engine!B$6+Engine!B$7))) -> 0 | D14: =IF(A14=0,0,(SUMPRODUCT((Engine!D$11:D$106<=A14)*Engine!D$11:D$106 + (Engine!D$11:D$106>A14)*A14)*Engine!B$1*Engine!B$6+SUMPRODUCT((Engine!E$11:E$106<=A14)*Engine!E$11:E$106 + (Engine!E$11:E$106>A14)*A14)*Engine!B$1*Engine!B$7)/(A14*60*144*(Engine!B$6+Engine!B$7))) -> 0.0010739537
A15: =A14+10 -> 130 | B15: =IF(A15=0,1,(SUMPRODUCT((Engine!D$11:D$106>A15)*(Engine!D$11:D$106-A15))*Engine!B$1*Engine!B$6+SUMPRODUCT((Engine!E$11:E$106>A15)*(Engine!E$11:E$106-A15))*Engine!B$1*Engine!B$7)/(Engine!H$15*Engine!B$6+Engine!H$16*Engine!B$7)) -> 0 | C15: =IF(A15=0,1,(COUNTIF(Engine!D$11:D$106,">"&A15)*Engine!B$6+COUNTIF(Engine!E$11:E$106,">"&A15)*Engine!B$7)/(ROWS(Engine!D$11:D$106)*(Engine!B$6+Engine!B$7))) -> 0 | D15: =IF(A15=0,0,(SUMPRODUCT((Engine!D$11:D$106<=A15)*Engine!D$11:D$106 + (Engine!D$11:D$106>A15)*A15)*Engine!B$1*Engine!B$6+SUMPRODUCT((Engine!E$11:E$106<=A15)*Engine!E$11:E$106 + (Engine!E$11:E$106>A15)*A15)*Engine!B$1*Engine!B$7)/(A15*60*154*(Engine!B$6+Engine!B$7))) -> 0.00092696905
A16: =A15+10 -> 140 | B16: =IF(A16=0,1,(SUMPRODUCT((Engine!D$11:D$106>A16)*(Engine!D$11:D$106-A16))*Engine!B$1*Engine!B$6+SUMPRODUCT((Engine!E$11:E$106>A16)*(Engine!E$11:E$106-A16))*Engine!B$1*Engine!B$7)/(Engine!H$15*Engine!B$6+Engine!H$16*Engine!B$7)) -> 0 | C16: =IF(A16=0,1,(COUNTIF(Engine!D$11:D$106,">"&A16)*Engine!B$6+COUNTIF(Engine!E$11:E$106,">"&A16)*Engine!B$7)/(ROWS(Engine!D$11:D$106)*(Engine!B$6+Engine!B$7))) -> 0 | D16: =IF(A16=0,0,(SUMPRODUCT((Engine!D$11:D$106<=A16)*Engine!D$11:D$106 + (Engine!D$11:D$106>A16)*A16)*Engine!B$1*Engine!B$6+SUMPRODUCT((Engine!E$11:E$106<=A16)*Engine!E$11:E$106 + (Engine!E$11:E$106>A16)*A16)*Engine!B$1*Engine!B$7)/(A16*60*164*(Engine!B$6+Engine!B$7))) -> 0.00080827179
A17: =A16+10 -> 150 | B17: =IF(A17=0,1,(SUMPRODUCT((Engine!D$11:D$106>A17)*(Engine!D$11:D$106-A17))*Engine!B$1*Engine!B$6+SUMPRODUCT((Engine!E$11:E$106>A17)*(Engine!E$11:E$106-A17))*Engine!B$1*Engine!B$7)/(Engine!H$15*Engine!B$6+Engine!H$16*Engine!B$7)) -> 0 | C17: =IF(A17=0,1,(COUNTIF(Engine!D$11:D$106,">"&A17)*Engine!B$6+COUNTIF(Engine!E$11:E$106,">"&A17)*Engine!B$7)/(ROWS(Engine!D$11:D$106)*(Engine!B$6+Engine!B$7))) -> 0 | D17: =IF(A17=0,0,(SUMPRODUCT((Engine!D$11:D$106<=A17)*Engine!D$11:D$106 + (Engine!D$11:D$106>A17)*A17)*Engine!B$1*Engine!B$6+SUMPRODUCT((Engine!E$11:E$106<=A17)*Engine!E$11:E$106 + (Engine!E$11:E$106>A17)*A17)*Engine!B$1*Engine!B$7)/(A17*60*174*(Engine!B$6+Engine!B$7))) -> 0.00071103143
A18: =A17+10 -> 160 | B18: =IF(A18=0,1,(SUMPRODUCT((Engine!D$11:D$106>A18)*(Engine!D$11:D$106-A18))*Engine!B$1*Engine!B$6+SUMPRODUCT((Engine!E$11:E$106>A18)*(Engine!E$11:E$106-A18))*Engine!B$1*Engine!B$7)/(Engine!H$15*Engine!B$6+Engine!H$16*Engine!B$7)) -> 0 | C18: =IF(A18=0,1,(COUNTIF(Engine!D$11:D$106,">"&A18)*Engine!B$6+COUNTIF(Engine!E$11:E$106,">"&A18)*Engine!B$7)/(ROWS(Engine!D$11:D$106)*(Engine!B$6+Engine!B$7))) -> 0 | D18: =IF(A18=0,0,(SUMPRODUCT((Engine!D$11:D$106<=A18)*Engine!D$11:D$106 + (Engine!D$11:D$106>A18)*A18)*Engine!B$1*Engine!B$6+SUMPRODUCT((Engine!E$11:E$106<=A18)*Engine!E$11:E$106 + (Engine!E$11:E$106>A18)*A18)*Engine!B$1*Engine!B$7)/(A18*60*184*(Engine!B$6+Engine!B$7))) -> 0.00063036414
A19: =A18+10 -> 170 | B19: =IF(A19=0,1,(SUMPRODUCT((Engine!D$11:D$106>A19)*(Engine!D$11:D$106-A19))*Engine!B$1*Engine!B$6+SUMPRODUCT((Engine!E$11:E$106>A19)*(Engine!E$11:E$106-A19))*Engine!B$1*Engine!B$7)/(Engine!H$15*Engine!B$6+Engine!H$16*Engine!B$7)) -> 0 | C19: =IF(A19=0,1,(COUNTIF(Engine!D$11:D$106,">"&A19)*Engine!B$6+COUNTIF(Engine!E$11:E$106,">"&A19)*Engine!B$7)/(ROWS(Engine!D$11:D$106)*(Engine!B$6+Engine!B$7))) -> 0 | D19: =IF(A19=0,0,(SUMPRODUCT((Engine!D$11:D$106<=A19)*Engine!D$11:D$106 + (Engine!D$11:D$106>A19)*A19)*Engine!B$1*Engine!B$6+SUMPRODUCT((Engine!E$11:E$106<=A19)*Engine!E$11:E$106 + (Engine!E$11:E$106>A19)*A19)*Engine!B$1*Engine!B$7)/(A19*60*194*(Engine!B$6+Engine!B$7))) -> 0.00056270226
A20: =A19+10 -> 180 | B20: =IF(A20=0,1,(SUMPRODUCT((Engine!D$11:D$106>A20)*(Engine!D$11:D$106-A20))*Engine!B$1*Engine!B$6+SUMPRODUCT((Engine!E$11:E$106>A20)*(Engine!E$11:E$106-A20))*Engine!B$1*Engine!B$7)/(Engine!H$15*Engine!B$6+Engine!H$16*Engine!B$7)) -> 0 | C20: =IF(A20=0,1,(COUNTIF(Engine!D$11:D$106,">"&A20)*Engine!B$6+COUNTIF(Engine!E$11:E$106,">"&A20)*Engine!B$7)/(ROWS(Engine!D$11:D$106)*(Engine!B$6+Engine!B$7))) -> 0 | D20: =IF(A20=0,0,(SUMPRODUCT((Engine!D$11:D$106<=A20)*Engine!D$11:D$106 + (Engine!D$11:D$106>A20)*A20)*Engine!B$1*Engine!B$6+SUMPRODUCT((Engine!E$11:E$106<=A20)*Engine!E$11:E$106 + (Engine!E$11:E$106>A20)*A20)*Engine!B$1*Engine!B$7)/(A20*60*204*(Engine!B$6+Engine!B$7))) -> 0.00050538999
A21: =A20+10 -> 190 | B21: =IF(A21=0,1,(SUMPRODUCT((Engine!D$11:D$106>A21)*(Engine!D$11:D$106-A21))*Engine!B$1*Engine!B$6+SUMPRODUCT((Engine!E$11:E$106>A21)*(Engine!E$11:E$106-A21))*Engine!B$1*Engine!B$7)/(Engine!H$15*Engine!B$6+Engine!H$16*Engine!B$7)) -> 0 | C21: =IF(A21=0,1,(COUNTIF(Engine!D$11:D$106,">"&A21)*Engine!B$6+COUNTIF(Engine!E$11:E$106,">"&A21)*Engine!B$7)/(ROWS(Engine!D$11:D$106)*(Engine!B$6+Engine!B$7))) -> 0 | D21: =IF(A21=0,0,(SUMPRODUCT((Engine!D$11:D$106<=A21)*Engine!D$11:D$106 + (Engine!D$11:D$106>A21)*A21)*Engine!B$1*Engine!B$6+SUMPRODUCT((Engine!E$11:E$106<=A21)*Engine!E$11:E$106 + (Engine!E$11:E$106>A21)*A21)*Engine!B$1*Engine!B$7)/(A21*60*214*(Engine!B$6+Engine!B$7))) -> 0.00045641713
A22: =A21+10 -> 200 | B22: =IF(A22=0,1,(SUMPRODUCT((Engine!D$11:D$106>A22)*(Engine!D$11:D$106-A22))*Engine!B$1*Engine!B$6+SUMPRODUCT((Engine!E$11:E$106>A22)*(Engine!E$11:E$106-A22))*Engine!B$1*Engine!B$7)/(Engine!H$15*Engine!B$6+Engine!H$16*Engine!B$7)) -> 0 | C22: =IF(A22=0,1,(COUNTIF(Engine!D$11:D$106,">"&A22)*Engine!B$6+COUNTIF(Engine!E$11:E$106,">"&A22)*Engine!B$7)/(ROWS(Engine!D$11:D$106)*(Engine!B$6+Engine!B$7))) -> 0 | D22: =IF(A22=0,0,(SUMPRODUCT((Engine!D$11:D$106<=A22)*Engine!D$11:D$106 + (Engine!D$11:D$106>A22)*A22)*Engine!B$1*Engine!B$6+SUMPRODUCT((Engine!E$11:E$106<=A22)*Engine!E$11:E$106 + (Engine!E$11:E$106>A22)*A22)*Engine!B$1*Engine!B$7)/(A22*60*224*(Engine!B$6+Engine!B$7))) -> 0.00041423929

Sheet QPM Estimator
A1: Input Data (per Hour)
A2: Peak Hour Usage Stats
A3: Average Number of Users | B3: 100
A4: Max Number of Users | B4: 600
A5: Average Number of Interactions (page Views in BI) | B5: 10
A6: Max Number of Interactions (Page views in BI) | B6: 10
A7: Average visit time duration (in minutes) | B7: 10
A8: Adoption Rate (%) | B8: 1
A9: SLA Guarantees (%) | B9: 0.99
A12: Per Minute Concurrent Users Stats
A13: Average number of concurrent users | B13: =B8*B3*B7/60 -> 16.666667
A14: Standard Deviation of Users per Hour | B14: =(B4-B3)/NORMINV(B9, 0, 1) -> 214.92916
A15: Standard Deviation of Users per minute | B15: =B14/SQRT(60) -> 27.747236
A16: Per minute max concurrent users at given SLA | B16: =B13+B15*NORMINV(B9,0,1) -> 81.216389 | F16: User Input to change
F17: Calculated field, do not change
A18: QPM Estimation Scenarios | F18: QPM Estimation, do not change
A19: Interaction speed with Genie is impacted by 3 factors: * Input latency: nb of seconds it takes to formalise a question * Genie Latency: nb of seconds it takes to answer a user question * Analysis latency: nb of seconds it takes to analyse Genie's resulta before eventually asking a follow-up question
A20: Scenari | B20: Interaction time in seconds | C20: QPM Estimation | F20: Example of BI traffic with global presence and 3 main hubs: Europe, East US and India
A21: Fast - small questions, easy to interpret the results | B21: 35 | C21: =B16*60/B21 -> 139.2281
A22: Standard | B22: 60 | C22: =B16*60/B22 -> 81.216389
A23: Slow - Complex question, need time to interpret results | B23: 65 | C23: =B16*60/B23 -> 74.968975
